Workbook
Name Padresverstrekker: Lening!$L$7:$M$7
Name GeleendBedrag: Lening!$D$3
Name Adresontvanger: Lening!$P$3
Name AccountNaam: 'CRM '!$A$2:$A$547
Name Pverstrekker: Lening!$L$6:$M$6
Name Naamverstrekker: Lening!$L$2:$M$2
Name BegindatumLening: Lening!$D$6
Name Naamontvanger: Lening!$P$2
Name Iban: Lening!$L$4:$M$4
Name CRM: 'CRM '!$A$2:$AO$547
Name Kenteken: Lening!$M$11
Name EersteBetaling: Lening!$C$10
Name Padresontvanger: Lening!$P$7
Name Adresverstrekker: Lening!$L$3:$M$3
Name Type: Lening!$M$14
Name Merk: Lening!$M$13
Name Verstrekker: Lening!$L$1
Name Veldnamenrij: Lening!$9:$9
Name TotaleRente: Lening!$H$5
Name Pontvanger: Lening!$P$6
Name Leningjaren: Lening!$D$5
Name TotaleLeningkosten: Lening!$H$6
Name PIban: Lening!$L$9:$M$9
Name VoertuigID: Lening!$M$12
Name Ontvanger: Lening!$P$1
Name AantalBetalingen: Lening!$H$4
Name Aflossing: Lening!$H$3
Name Rentevoet: Lening!$D$4

Sheet CRM 
A1: =IFERROR(__xludf.DUMMYFUNCTION("IMPORTRANGE(""1GdTinF6-0i_lvTatB4CP3cB__lgNzE6_ZfISkzeXnv8"",""CRM!A2:AO"")"),"KvKNaam") -> KvKNaam | B1: =IFERROR(__xludf.DUMMYFUNCTION("""COMPUTED_VALUE"""),"Bedrijfsnaam") -> Bedrijfsnaam | C1: =IFERROR(__xludf.DUMMYFUNCTION("""COMPUTED_VALUE"""),"Map") -> Map | D1: =IFERROR(__xludf.DUMMYFUNCTION("""COMPUTED_VALUE"""),"Eigendom") -> Eigendom | E1: =IFERROR(__xludf.DUMMYFUNCTION("""COMPUTED_VALUE"""),"SBI_Code") -> SBI_Code | F1: =IFERROR(__xludf.DUMMYFUNCTION("""COMPUTED_VALUE"""),"HoofdTel") -> HoofdTel | G1: =IFERROR(__xludf.DUMMYFUNCTION("""COMPUTED_VALUE"""),"Email1Acc") -> Email1Acc | H1: =IFERROR(__xludf.DUMMYFUNCTION("""COMPUTED_VALUE"""),"StraatFactuur") -> StraatFactuur | I1: =IFERROR(__xludf.DUMMYFUNCTION("""COMPUTED_VALUE"""),"PCFactuur") -> PCFactuur | J1: =IFERROR(__xludf.DUMMYFUNCTION("""COMPUTED_VALUE"""),"PlaatsFactuur") -> PlaatsFactuur | K1: =IFERROR(__xludf.DUMMYFUNCTION("""COMPUTED_VALUE"""),"LandFactuur") -> LandFactuur | L1: =IFERROR(__xludf.DUMMYFUNCTION("""COMPUTED_VALUE"""),"BulgaarseNaam") -> BulgaarseNaam | M1: =IFERROR(__xludf.DUMMYFUNCTION("""COMPUTED_VALUE"""),"KlantVanaf") -> KlantVanaf | N1: =IFERROR(__xludf.DUMMYFUNCTION("""COMPUTED_VALUE"""),"BTWNummer") -> BTWNummer | O1: =IFERROR(__xludf.DUMMYFUNCTION("""COMPUTED_VALUE"""),"KvKNummer") -> KvKNummer | P1: =IFERROR(__xludf.DUMMYFUNCTION("""COMPUTED_VALUE"""),"IBANZakelijk") -> IBANZakelijk | Q1: =IFERROR(__xludf.DUMMYFUNCTION("""COMPUTED_VALUE"""),"KvKInschrijving") -> KvKInschrijving | R1: =IFERROR(__xludf.DUMMYFUNCTION("""COMPUTED_VALUE"""),"KvKUitschrijving") -> KvKUitschrijving | S1: =IFERROR(__xludf.DUMMYFUNCTION("""COMPUTED_VALUE"""),"BTWID") -> BTWID | T1: =IFERROR(__xludf.DUMMYFUNCTION("""COMPUTED_VALUE"""),"RSIN") -> RSIN | U1: =IFERROR(__xludf.DUMMYFUNCTION("""COMPUTED_VALUE"""),"Rechtsvorm") -> Rechtsvorm | V1: =IFERROR(__xludf.DUMMYFUNCTION("""COMPUTED_VALUE"""),"KvKVestigingsnummer") -> KvKVestigingsnummer | W1: =IFERROR(__xludf.DUMMYFUNCTION("""COMPUTED_VALUE"""),"EmailInkopen") -> EmailInkopen | X1: =IFERROR(__xludf.DUMMYFUNCTION("""COMPUTED_VALUE"""),"EmailVerkopen") -> EmailVerkopen | Y1: =IFERROR(__xludf.DUMMYFUNCTION("""COMPUTED_VALUE"""),"Aanhef") -> Aanhef | Z1: =IFERROR(__xludf.DUMMYFUNCTION("""COMPUTED_VALUE"""),"Voornaam") -> Voornaam | AA1: =IFERROR(__xludf.DUMMYFUNCTION("""COMPUTED_VALUE"""),"Achternaam") -> Achternaam | AB1: =IFERROR(__xludf.DUMMYFUNCTION("""COMPUTED_VALUE"""),"Voorletters") -> Voorletters | AC1: =IFERROR(__xludf.DUMMYFUNCTION("""COMPUTED_VALUE"""),"BSN") -> BSN | AD1: =IFERROR(__xludf.DUMMYFUNCTION("""COMPUTED_VALUE"""),"GeborteDatum") -> GeborteDatum | AE1: =IFERROR(__xludf.DUMMYFUNCTION("""COMPUTED_VALUE"""),"Taal") -> Taal | AF1: =IFERROR(__xludf.DUMMYFUNCTION("""COMPUTED_VALUE"""),"GeboortePlaats") -> GeboortePlaats | AG1: =IFERROR(__xludf.DUMMYFUNCTION("""COMPUTED_VALUE"""),"VolNaam") -> VolNaam | AH1: =IFERROR(__xludf.DUMMYFUNCTION("""COMPUTED_VALUE"""),"IBAN Prive") -> IBAN Prive | AI1: =IFERROR(__xludf.DUMMYFUNCTION("""COMPUTED_VALUE"""),"GBAReg") -> GBAReg | AJ1: =IFERROR(__xludf.DUMMYFUNCTION("""COMPUTED_VALUE"""),"IDSoort") -> IDSoort | AK1: =IFERROR(__xludf.DUMMYFUNCTION("""COMPUTED_VALUE"""),"IDNummer") -> IDNummer | AL1: =IFERROR(__xludf.DUMMYFUNCTION("""COMPUTED_VALUE"""),"IDVerloop") -> IDVerloop | AM1: =IFERROR(__xludf.DUMMYFUNCTION("""COMPUTED_VALUE"""),"GebLand") -> GebLand | AN1: =IFERROR(__xludf.DUMMYFUNCTION("""COMPUTED_VALUE"""),"CNaam") -> CNaam | AO1: =IFERROR(__xludf.DUMMYFUNCTION("""COMPUTED_VALUE"""),"KlantNr") -> KlantNr
A2: =IFERROR(__xludf.DUMMYFUNCTION("""COMPUTED_VALUE"""),"A. Georgiev") -> A. Georgiev | B2: =IFERROR(__xludf.DUMMYFUNCTION("""COMPUTED_VALUE"""),"A. Georgiev Services") -> A. Georgiev Services | C2: =IFERROR(__xludf.DUMMYFUNCTION("""COMPUTED_VALUE"""),1051.0) -> 1051 | D2: =IFERROR(__xludf.DUMMYFUNCTION("""COMPUTED_VALUE"""),"Anton Pavlov Georgiev") -> Anton Pavlov Georgiev | E2: =IFERROR(__xludf.DUMMYFUNCTION("""COMPUTED_VALUE"""),"SBI-code: 4120 - Algemene burgerlijke en utiliteitsbouw") -> SBI-code: 4120 - Algemene burgerlijke en utiliteitsbouw | F2: =IFERROR(__xludf.DUMMYFUNCTION("""COMPUTED_VALUE"""),"0649674189") -> 0649674189 | G2: =IFERROR(__xludf.DUMMYFUNCTION("""COMPUTED_VALUE"""),"antonfant@gmail.com") -> antonfant@gmail.com | H2: =IFERROR(__xludf.DUMMYFUNCTION("""COMPUTED_VALUE"""),"Aaraustraat 19") -> Aaraustraat 19 | I2: =IFERROR(__xludf.DUMMYFUNCTION("""COMPUTED_VALUE"""),"2612BP") -> 2612BP | J2: =IFERROR(__xludf.DUMMYFUNCTION("""COMPUTED_VALUE"""),"Delft") -> Delft | K2: =IFERROR(__xludf.DUMMYFUNCTION("""COMPUTED_VALUE"""),"Nederland") -> Nederland | L2: =IFERROR(__xludf.DUMMYFUNCTION("""COMPUTED_VALUE"""),"Георгиев") -> Георгиев | M2: =IFERROR(__xludf.DUMMYFUNCTION("""COMPUTED_VALUE"""),44193.0) -> 44193 | N2: =IFERROR(__xludf.DUMMYFUNCTION("""COMPUTED_VALUE"""),"NL693607014B02") -> NL693607014B02 | O2: =IFERROR(__xludf.DUMMYFUNCTION("""COMPUTED_VALUE"""),9.9942506E7) -> 99942506 | P2: =IFERROR(__xludf.DUMMYFUNCTION("""COMPUTED_VALUE"""),"NL") -> NL | Q2: =IFERROR(__xludf.DUMMYFUNCTION("""COMPUTED_VALUE"""),45992.0) -> 45992 | S2: =IFERROR(__xludf.DUMMYFUNCTION("""COMPUTED_VALUE"""),"NL005365781B76") -> NL005365781B76 | T2: =IFERROR(__xludf.DUMMYFUNCTION("""COMPUTED_VALUE"""),6.93607014E8) -> 693607014 | U2: =IFERROR(__xludf.DUMMYFUNCTION("""COMPUTED_VALUE"""),"Eenmanszaak") -> Eenmanszaak | V2: =IFERROR(__xludf.DUMMYFUNCTION("""COMPUTED_VALUE"""),"000064070603") -> 000064070603 | W2: =IFERROR(__xludf.DUMMYFUNCTION("""COMPUTED_VALUE"""),"ink.a.georgiev.2288aa@zarabota.nl") -> ink.a.georgiev.2288aa@zarabota.nl | X2: =IFERROR(__xludf.DUMMYFUNCTION("""COMPUTED_VALUE"""),"ver.a.georgiev.2288aa@zarabota.nl") -> ver.a.georgiev.2288aa@zarabota.nl | Y2: =IFERROR(__xludf.DUMMYFUNCTION("""COMPUTED_VALUE"""),"Hr.") -> Hr. | Z2: =IFERROR(__xludf.DUMMYFUNCTION("""COMPUTED_VALUE"""),"Anton Pavlov") -> Anton Pavlov | AA2: =IFERROR(__xludf.DUMMYFUNCTION("""COMPUTED_VALUE"""),"Georgiev") -> Georgiev | AB2: =IFERROR(__xludf.DUMMYFUNCTION("""COMPUTED_VALUE"""),"A.P.") -> A.P. | AC2: =IFERROR(__xludf.DUMMYFUNCTION("""COMPUTED_VALUE"""),6.93607014E8) -> 693607014 | AD2: =IFERROR(__xludf.DUMMYFUNCTION("""COMPUTED_VALUE"""),28738.0) -> 28738 | AE2: =IFERROR(__xludf.DUMMYFUNCTION("""COMPUTED_VALUE"""),"bg") -> bg | AF2: =IFERROR(__xludf.DUMMYFUNCTION("""COMPUTED_VALUE"""),"Sofia") -> Sofia | AG2: =IFERROR(__xludf.DUMMYFUNCTION("""COMPUTED_VALUE"""),"Hr. A.P. Georgiev") -> Hr. A.P. Georgiev | AJ2: =IFERROR(__xludf.DUMMYFUNCTION("""COMPUTED_VALUE"""),"ID Kaart") -> ID Kaart | AK2: =IFERROR(__xludf.DUMMYFUNCTION("""COMPUTED_VALUE"""),6.46497506E8) -> 646497506 | AL2: =IFERROR(__xludf.DUMMYFUNCTION("""COMPUTED_VALUE"""),46201.0) -> 46201 | AM2: =IFERROR(__xludf.DUMMYFUNCTION("""COMPUTED_VALUE"""),"Bulgarije") -> Bulgarije | AN2: =IFERROR(__xludf.DUMMYFUNCTION("""COMPUTED_VALUE"""),"Anton Pavlov Georgiev") -> Anton Pavlov Georgiev | AO2: =IFERROR(__xludf.DUMMYFUNCTION("""COMPUTED_VALUE"""),1051.0) -> 1051
A3: =IFERROR(__xludf.DUMMYFUNCTION("""COMPUTED_VALUE"""),"A. Iliev") -> A. Iliev | B3: =IFERROR(__xludf.DUMMYFUNCTION("""COMPUTED_VALUE"""),"A. Iliev") -> A. Iliev | C3: =IFERROR(__xludf.DUMMYFUNCTION("""COMPUTED_VALUE"""),1333.0) -> 1333 | D3: =IFERROR(__xludf.DUMMYFUNCTION("""COMPUTED_VALUE"""),"Aleksandar Nikolaev Iliev") -> Aleksandar Nikolaev Iliev | E3: =IFERROR(__xludf.DUMMYFUNCTION("""COMPUTED_VALUE"""),"SBI-code: 4120 - Algemene burgerlijke en utiliteitsbouw") -> SBI-code: 4120 - Algemene burgerlijke en utiliteitsbouw | F3: =IFERROR(__xludf.DUMMYFUNCTION("""COMPUTED_VALUE"""),"+359882707869") -> +359882707869 | G3: =IFERROR(__xludf.DUMMYFUNCTION("""COMPUTED_VALUE"""),"aleksandur91@gmail.com") -> aleksandur91@gmail.com | H3: =IFERROR(__xludf.DUMMYFUNCTION("""COMPUTED_VALUE"""),"Springersdiep 21") -> Springersdiep 21 | I3: =IFERROR(__xludf.DUMMYFUNCTION("""COMPUTED_VALUE"""),"2904ET") -> 2904ET | J3: =IFERROR(__xludf.DUMMYFUNCTION("""COMPUTED_VALUE"""),"Capelle aan den IJssel") -> Capelle aan den IJssel | K3: =IFERROR(__xludf.DUMMYFUNCTION("""COMPUTED_VALUE"""),"Nederland") -> Nederland | L3: =IFERROR(__xludf.DUMMYFUNCTION("""COMPUTED_VALUE"""),"Илиев") -> Илиев | M3: =IFERROR(__xludf.DUMMYFUNCTION("""COMPUTED_VALUE"""),44606.0) -> 44606 | N3: =IFERROR(__xludf.DUMMYFUNCTION("""COMPUTED_VALUE"""),"NL694524268B01") -> NL694524268B01 | O3: =IFERROR(__xludf.DUMMYFUNCTION("""COMPUTED_VALUE"""),8.5495239E7) -> 85495239 | P3: =IFERROR(__xludf.DUMMYFUNCTION("""COMPUTED_VALUE"""),"NL27INGB0390009083") -> NL27INGB0390009083 | Q3: =IFERROR(__xludf.DUMMYFUNCTION("""COMPUTED_VALUE"""),44606.0) -> 44606 | S3: =IFERROR(__xludf.DUMMYFUNCTION("""COMPUTED_VALUE"""),"NL004103132B76") -> NL004103132B76 | T3: =IFERROR(__xludf.DUMMYFUNCTION("""COMPUTED_VALUE"""),6.94524268E8) -> 694524268 | U3: =IFERROR(__xludf.DUMMYFUNCTION("""COMPUTED_VALUE"""),"Eenmanszaak") -> Eenmanszaak | V3: =IFERROR(__xludf.DUMMYFUNCTION("""COMPUTED_VALUE"""),"000051537753") -> 000051537753 | W3: =IFERROR(__xludf.DUMMYFUNCTION("""COMPUTED_VALUE"""),"ink.ailiev.2288aa@zarabota.nl") -> ink.ailiev.2288aa@zarabota.nl | X3: =IFERROR(__xludf.DUMMYFUNCTION("""COMPUTED_VALUE"""),"ver.ailiev.2288aa@zarabota.nl") -> ver.ailiev.2288aa@zarabota.nl | Y3: =IFERROR(__xludf.DUMMYFUNCTION("""COMPUTED_VALUE"""),"Hr.") -> Hr. | Z3: =IFERROR(__xludf.DUMMYFUNCTION("""COMPUTED_VALUE"""),"Aleksandar Nikolaev") -> Aleksandar Nikolaev | AA3: =IFERROR(__xludf.DUMMYFUNCTION("""COMPUTED_VALUE"""),"Iliev") -> Iliev | AB3: =IFERROR(__xludf.DUMMYFUNCTION("""COMPUTED_VALUE"""),"A.N.") -> A.N. | AC3: =IFERROR(__xludf.DUMMYFUNCTION("""COMPUTED_VALUE"""),6.94524268E8) -> 694524268 | AD3: =IFERROR(__xludf.DUMMYFUNCTION("""COMPUTED_VALUE"""),34490.0) -> 34490 | AE3: =IFERROR(__xludf.DUMMYFUNCTION("""COMPUTED_VALUE"""),"bg") -> bg | AF3: =IFERROR(__xludf.DUMMYFUNCTION("""COMPUTED_VALUE"""),"Veliko Tarnovo") -> Veliko Tarnovo | AG3: =IFERROR(__xludf.DUMMYFUNCTION("""COMPUTED_VALUE"""),"Hr. A.N. Iliev") -> Hr. A.N. Iliev | AJ3: =IFERROR(__xludf.DUMMYFUNCTION("""COMPUTED_VALUE"""),"ID Kaart") -> ID Kaart | AK3: =IFERROR(__xludf.DUMMYFUNCTION("""COMPUTED_VALUE"""),6.51372198E8) -> 651372198 | AL3: =IFERROR(__xludf.DUMMYFUNCTION("""COMPUTED_VALUE"""),48211.0) -> 48211 | AM3: =IFERROR(__xludf.DUMMYFUNCTION("""COMPUTED_VALUE"""),"Bulgarije") -> Bulgarije | AN3: =IFERROR(__xludf.DUMMYFUNCTION("""COMPUTED_VALUE"""),"Aleksandar Nikolaev Iliev") -> Aleksandar Nikolaev Iliev | AO3: =IFERROR(__xludf.DUMMYFUNCTION("""COMPUTED_VALUE"""),1333.0) -> 1333
A4: =IFERROR(__xludf.DUMMYFUNCTION("""COMPUTED_VALUE"""),"A.A. Kazakov") -> A.A. Kazakov | B4: =IFERROR(__xludf.DUMMYFUNCTION("""COMPUTED_VALUE"""),"A.A. Kazakov") -> A.A. Kazakov | C4: =IFERROR(__xludf.DUMMYFUNCTION("""COMPUTED_VALUE"""),1074.0) -> 1074 | D4: =IFERROR(__xludf.DUMMYFUNCTION("""COMPUTED_VALUE"""),"Asen Andreev Kazakov") -> Asen Andreev Kazakov | E4: =IFERROR(__xludf.DUMMYFUNCTION("""COMPUTED_VALUE"""),"SBI-code: 4120 - Algemene burgerlijke en utiliteitsbouw") -> SBI-code: 4120 - Algemene burgerlijke en utiliteitsbouw | F4: =IFERROR(__xludf.DUMMYFUNCTION("""COMPUTED_VALUE"""),"0685411440") -> 0685411440 | G4: =IFERROR(__xludf.DUMMYFUNCTION("""COMPUTED_VALUE"""),"kazakovasen5@gmail.com") -> kazakovasen5@gmail.com | H4: =IFERROR(__xludf.DUMMYFUNCTION("""COMPUTED_VALUE"""),"Loosduinseweg 867") -> Loosduinseweg 867 | I4: =IFERROR(__xludf.DUMMYFUNCTION("""COMPUTED_VALUE"""),"2571AV") -> 2571AV | J4: =IFERROR(__xludf.DUMMYFUNCTION("""COMPUTED_VALUE"""),"s-Gravenhage") -> s-Gravenhage | K4: =IFERROR(__xludf.DUMMYFUNCTION("""COMPUTED_VALUE"""),"Nederland") -> Nederland | L4: =IFERROR(__xludf.DUMMYFUNCTION("""COMPUTED_VALUE"""),"Казаков") -> Казаков | M4: =IFERROR(__xludf.DUMMYFUNCTION("""COMPUTED_VALUE"""),44238.0) -> 44238 | N4: =IFERROR(__xludf.DUMMYFUNCTION("""COMPUTED_VALUE"""),"NL673253570B01") -> NL673253570B01 | O4: =IFERROR(__xludf.DUMMYFUNCTION("""COMPUTED_VALUE"""),8.2225443E7) -> 82225443 | P4: =IFERROR(__xludf.DUMMYFUNCTION("""COMPUTED_VALUE"""),"NL87INGB0007300808") -> NL87INGB0007300808 | Q4: =IFERROR(__xludf.DUMMYFUNCTION("""COMPUTED_VALUE"""),44238.0) -> 44238 | S4: =IFERROR(__xludf.DUMMYFUNCTION("""COMPUTED_VALUE"""),"NL003657916B47") -> NL003657916B47 | T4: =IFERROR(__xludf.DUMMYFUNCTION("""COMPUTED_VALUE"""),6.7325357E8) -> 673253570 | U4: =IFERROR(__xludf.DUMMYFUNCTION("""COMPUTED_VALUE"""),"Eenmanszaak") -> Eenmanszaak | V4: =IFERROR(__xludf.DUMMYFUNCTION("""COMPUTED_VALUE"""),"000048473502") -> 000048473502 | W4: =IFERROR(__xludf.DUMMYFUNCTION("""COMPUTED_VALUE"""),"ink.aakazakov.2288aa@zarabota.nl") -> ink.aakazakov.2288aa@zarabota.nl | X4: =IFERROR(__xludf.DUMMYFUNCTION("""COMPUTED_VALUE"""),"ver.aakazakov.2288aa@zarabota.nl") -> ver.aakazakov.2288aa@zarabota.nl | Y4: =IFERROR(__xludf.DUMMYFUNCTION("""COMPUTED_VALUE"""),"Hr.") -> Hr. | Z4: =IFERROR(__xludf.DUMMYFUNCTION("""COMPUTED_VALUE"""),"Asen Andreev") -> Asen Andreev | AA4: =IFERROR(__xludf.DUMMYFUNCTION("""COMPUTED_VALUE"""),"Kazakov") -> Kazakov | AB4: =IFERROR(__xludf.DUMMYFUNCTION("""COMPUTED_VALUE"""),"A.A.") -> A.A. | AC4: =IFERROR(__xludf.DUMMYFUNCTION("""COMPUTED_VALUE"""),6.7325357E8) -> 673253570 | AD4: =IFERROR(__xludf.DUMMYFUNCTION("""COMPUTED_VALUE"""),28527.0) -> 28527 | AE4: =IFERROR(__xludf.DUMMYFUNCTION("""COMPUTED_VALUE"""),"bg") -> bg | AF4: =IFERROR(__xludf.DUMMYFUNCTION("""COMPUTED_VALUE"""),"Svilengrad") -> Svilengrad | AG4: =IFERROR(__xludf.DUMMYFUNCTION("""COMPUTED_VALUE"""),"Hr. A.A. Kazakov") -> Hr. A.A. Kazakov | AH4: =IFERROR(__xludf.DUMMYFUNCTION("""COMPUTED_VALUE"""),"NL46INGB0796616833") -> NL46INGB0796616833 | AI4: =IFERROR(__xludf.DUMMYFUNCTION("""COMPUTED_VALUE"""),43727.0) -> 43727 | AJ4: =IFERROR(__xludf.DUMMYFUNCTION("""COMPUTED_VALUE"""),"ID Kaart") -> ID Kaart | AK4: =IFERROR(__xludf.DUMMYFUNCTION("""COMPUTED_VALUE"""),6.46715056E8) -> 646715056 | AL4: =IFERROR(__xludf.DUMMYFUNCTION("""COMPUTED_VALUE"""),46323.0) -> 46323 | AM4: =IFERROR(__xludf.DUMMYFUNCTION("""COMPUTED_VALUE"""),"Bulgarije") -> Bulgarije | AN4: =IFERROR(__xludf.DUMMYFUNCTION("""COMPUTED_VALUE"""),"Asen Andreev Kazakov") -> Asen Andreev Kazakov | AO4: =IFERROR(__xludf.DUMMYFUNCTION("""COMPUTED_VALUE"""),1074.0) -> 1074
A5: =IFERROR(__xludf.DUMMYFUNCTION("""COMPUTED_VALUE"""),"A.B. Mitev") -> A.B. Mitev | B5: =IFERROR(__xludf.DUMMYFUNCTION("""COMPUTED_VALUE"""),"A.B. Mitev") -> A.B. Mitev | C5: =IFERROR(__xludf.DUMMYFUNCTION("""COMPUTED_VALUE"""),923.0) -> 923 | D5: =IFERROR(__xludf.DUMMYFUNCTION("""COMPUTED_VALUE"""),"Atanas Borisov Mitev") -> Atanas Borisov Mitev | E5: =IFERROR(__xludf.DUMMYFUNCTION("""COMPUTED_VALUE"""),"SBI-code: 4120 - Algemene burgerlijke en utiliteitsbouw") -> SBI-code: 4120 - Algemene burgerlijke en utiliteitsbouw | F5: =IFERROR(__xludf.DUMMYFUNCTION("""COMPUTED_VALUE"""),"0684083090") -> 0684083090 | G5: =IFERROR(__xludf.DUMMYFUNCTION("""COMPUTED_VALUE"""),"atanas.borisov.mitev@gmail.com") -> atanas.borisov.mitev@gmail.com | H5: =IFERROR(__xludf.DUMMYFUNCTION("""COMPUTED_VALUE"""),"Dautzenbergstraat 21") -> Dautzenbergstraat 21 | I5: =IFERROR(__xludf.DUMMYFUNCTION("""COMPUTED_VALUE"""),"2523KB") -> 2523KB | J5: =IFERROR(__xludf.DUMMYFUNCTION("""COMPUTED_VALUE"""),"s-Gravenhage") -> s-Gravenhage | K5: =IFERROR(__xludf.DUMMYFUNCTION("""COMPUTED_VALUE"""),"Nederland") -> Nederland | L5: =IFERROR(__xludf.DUMMYFUNCTION("""COMPUTED_VALUE"""),"Митев") -> Митев | M5: =IFERROR(__xludf.DUMMYFUNCTION("""COMPUTED_VALUE"""),43881.0) -> 43881 | N5: =IFERROR(__xludf.DUMMYFUNCTION("""COMPUTED_VALUE"""),"NL454395681B02") -> NL454395681B02 | O5: =IFERROR(__xludf.DUMMYFUNCTION("""COMPUTED_VALUE"""),7.6889084E7) -> 76889084 | P5: =IFERROR(__xludf.DUMMYFUNCTION("""COMPUTED_VALUE"""),"NL91INGB0007017981") -> NL91INGB0007017981 | Q5: =IFERROR(__xludf.DUMMYFUNCTION("""COMPUTED_VALUE"""),43836.0) -> 43836 | S5: =IFERROR(__xludf.DUMMYFUNCTION("""COMPUTED_VALUE"""),"NL003142606B73") -> NL003142606B73 | T5: =IFERROR(__xludf.DUMMYFUNCTION("""COMPUTED_VALUE"""),4.54395681E8) -> 454395681 | U5: =IFERROR(__xludf.DUMMYFUNCTION("""COMPUTED_VALUE"""),"Eenmanszaak") -> Eenmanszaak | V5: =IFERROR(__xludf.DUMMYFUNCTION("""COMPUTED_VALUE"""),"000044627726") -> 000044627726 | W5: =IFERROR(__xludf.DUMMYFUNCTION("""COMPUTED_VALUE"""),"ink.a.b.mitev.2288aa@zarabota.nl") -> ink.a.b.mitev.2288aa@zarabota.nl | X5: =IFERROR(__xludf.DUMMYFUNCTION("""COMPUTED_VALUE"""),"ver.a.b.mitev.2288aa@zarabota.nl") -> ver.a.b.mitev.2288aa@zarabota.nl | Y5: =IFERROR(__xludf.DUMMYFUNCTION("""COMPUTED_VALUE"""),"Hr.") -> Hr. | Z5: =IFERROR(__xludf.DUMMYFUNCTION("""COMPUTED_VALUE"""),"Atanas Borisov") -> Atanas Borisov | AA5: =IFERROR(__xludf.DUMMYFUNCTION("""COMPUTED_VALUE"""),"Mitev") -> Mitev | AB5: =IFERROR(__xludf.DUMMYFUNCTION("""COMPUTED_VALUE"""),"A.B.") -> A.B. | AC5: =IFERROR(__xludf.DUMMYFUNCTION("""COMPUTED_VALUE"""),4.54395681E8) -> 454395681 | AD5: =IFERROR(__xludf.DUMMYFUNCTION("""COMPUTED_VALUE"""),27306.0) -> 27306 | AE5: =IFERROR(__xludf.DUMMYFUNCTION("""COMPUTED_VALUE"""),"bg") -> bg | AF5: =IFERROR(__xludf.DUMMYFUNCTION("""COMPUTED_VALUE"""),"Parvomay") -> Parvomay | AG5: =IFERROR(__xludf.DUMMYFUNCTION("""COMPUTED_VALUE"""),"Hr. A.B. Mitev") -> Hr. A.B. Mitev | AH5: =IFERROR(__xludf.DUMMYFUNCTION("""COMPUTED_VALUE"""),"NL56INGB0676666841") -> NL56INGB0676666841 | AJ5: =IFERROR(__xludf.DUMMYFUNCTION("""COMPUTED_VALUE"""),"ID Kaart") -> ID Kaart | AK5: =IFERROR(__xludf.DUMMYFUNCTION("""COMPUTED_VALUE"""),6.45147859E8) -> 645147859 | AL5: =IFERROR(__xludf.DUMMYFUNCTION("""COMPUTED_VALUE"""),45404.0) -> 45404 | AM5: =IFERROR(__xludf.DUMMYFUNCTION("""COMPUTED_VALUE"""),"Bulgarije") -> Bulgarije | AN5: =IFERROR(__xludf.DUMMYFUNCTION("""COMPUTED_VALUE"""),"Atanas Borisov Mitev") -> Atanas Borisov Mitev
A6: =IFERROR(__xludf.DUMMYFUNCTION("""COMPUTED_VALUE"""),"A.R.S. 89") -> A.R.S. 89 | B6: =IFERROR(__xludf.DUMMYFUNCTION("""COMPUTED_VALUE"""),"A.R.S. 89") -> A.R.S. 89 | C6: =IFERROR(__xludf.DUMMYFUNCTION("""COMPUTED_VALUE"""),672.0) -> 672 | D6: =IFERROR(__xludf.DUMMYFUNCTION("""COMPUTED_VALUE"""),"Aliosman Ramadan Shefket") -> Aliosman Ramadan Shefket | E6: =IFERROR(__xludf.DUMMYFUNCTION("""COMPUTED_VALUE"""),"SBI-code: 4120 - Algemene burgerlijke en utiliteitsbouw") -> SBI-code: 4120 - Algemene burgerlijke en utiliteitsbouw | F6: =IFERROR(__xludf.DUMMYFUNCTION("""COMPUTED_VALUE"""),"0638663285") -> 0638663285 | G6: =IFERROR(__xludf.DUMMYFUNCTION("""COMPUTED_VALUE"""),"aliosman123987@abv.bg") -> aliosman123987@abv.bg | H6: =IFERROR(__xludf.DUMMYFUNCTION("""COMPUTED_VALUE"""),"Jan van der Heijdenstraat 90") -> Jan van der Heijdenstraat 90 | I6: =IFERROR(__xludf.DUMMYFUNCTION("""COMPUTED_VALUE"""),"2522ES") -> 2522ES | J6: =IFERROR(__xludf.DUMMYFUNCTION("""COMPUTED_VALUE"""),"s-Gravenhage") -> s-Gravenhage | K6: =IFERROR(__xludf.DUMMYFUNCTION("""COMPUTED_VALUE"""),"Nederland") -> Nederland | L6: =IFERROR(__xludf.DUMMYFUNCTION("""COMPUTED_VALUE"""),"Шефкет") -> Шефкет | M6: =IFERROR(__xludf.DUMMYFUNCTION("""COMPUTED_VALUE"""),43472.0) -> 43472 | N6: =IFERROR(__xludf.DUMMYFUNCTION("""COMPUTED_VALUE"""),"NL395720655B01") -> NL395720655B01 | O6: =IFERROR(__xludf.DUMMYFUNCTION("""COMPUTED_VALUE"""),7.3604445E7) -> 73604445 | P6: =IFERROR(__xludf.DUMMYFUNCTION("""COMPUTED_VALUE"""),"NL64INGB0009118711") -> NL64INGB0009118711 | Q6: =IFERROR(__xludf.DUMMYFUNCTION("""COMPUTED_VALUE"""),43472.0) -> 43472 | S6: =IFERROR(__xludf.DUMMYFUNCTION("""COMPUTED_VALUE"""),"NL002478396B47") -> NL002478396B47 | T6: =IFERROR(__xludf.DUMMYFUNCTION("""COMPUTED_VALUE"""),3.95720655E8) -> 395720655 | U6: =IFERROR(__xludf.DUMMYFUNCTION("""COMPUTED_VALUE"""),"Eenmanszaak") -> Eenmanszaak | V6: =IFERROR(__xludf.DUMMYFUNCTION("""COMPUTED_VALUE"""),"000041623010") -> 000041623010 | W6: =IFERROR(__xludf.DUMMYFUNCTION("""COMPUTED_VALUE"""),"ink.a.r.s.89.2288aa@zarabota.nl") -> ink.a.r.s.89.2288aa@zarabota.nl | X6: =IFERROR(__xludf.DUMMYFUNCTION("""COMPUTED_VALUE"""),"ver.a.r.s.89.2288aa@zarabota.nl") -> ver.a.r.s.89.2288aa@zarabota.nl | Y6: =IFERROR(__xludf.DUMMYFUNCTION("""COMPUTED_VALUE"""),"Hr.") -> Hr. | Z6: =IFERROR(__xludf.DUMMYFUNCTION("""COMPUTED_VALUE"""),"Aliosman Ramadan") -> Aliosman Ramadan | AA6: =IFERROR(__xludf.DUMMYFUNCTION("""COMPUTED_VALUE"""),"Shefket") -> Shefket | AB6: =IFERROR(__xludf.DUMMYFUNCTION("""COMPUTED_VALUE"""),"A.R.") -> A.R. | AC6: =IFERROR(__xludf.DUMMYFUNCTION("""COMPUTED_VALUE"""),3.95720655E8) -> 395720655 | AD6: =IFERROR(__xludf.DUMMYFUNCTION("""COMPUTED_VALUE"""),32662.0) -> 32662 | AE6: =IFERROR(__xludf.DUMMYFUNCTION("""COMPUTED_VALUE"""),"bg") -> bg | AF6: =IFERROR(__xludf.DUMMYFUNCTION("""COMPUTED_VALUE"""),"Haskovo") -> Haskovo | AG6: =IFERROR(__xludf.DUMMYFUNCTION("""COMPUTED_VALUE"""),"Hr. A.R. Shefket") -> Hr. A.R. Shefket | AN6: =IFERROR(__xludf.DUMMYFUNCTION("""COMPUTED_VALUE"""),"Aliosman Ramadan Shefket") -> Aliosman Ramadan Shefket
A7: =IFERROR(__xludf.DUMMYFUNCTION("""COMPUTED_VALUE"""),"A1 Maatwerk B.V.") -> A1 Maatwerk B.V. | B7: =IFERROR(__xludf.DUMMYFUNCTION("""COMPUTED_VALUE"""),"A1 Maatwerk B.V.") -> A1 Maatwerk B.V. | C7: =IFERROR(__xludf.DUMMYFUNCTION("""COMPUTED_VALUE"""),1750.0) -> 1750 | D7: =IFERROR(__xludf.DUMMYFUNCTION("""COMPUTED_VALUE"""),"Anatoliy Viktorovich Volyanyuk") -> Anatoliy Viktorovich Volyanyuk | E7: =IFERROR(__xludf.DUMMYFUNCTION("""COMPUTED_VALUE"""),"SBI-code: 4120 - Algemene burgerlijke en utiliteitsbouw") -> SBI-code: 4120 - Algemene burgerlijke en utiliteitsbouw | F7: =IFERROR(__xludf.DUMMYFUNCTION("""COMPUTED_VALUE"""),"0612374803") -> 0612374803 | G7: =IFERROR(__xludf.DUMMYFUNCTION("""COMPUTED_VALUE"""),"a1maatwerkbv@gmail.com") -> a1maatwerkbv@gmail.com | H7: =IFERROR(__xludf.DUMMYFUNCTION("""COMPUTED_VALUE"""),"B. Thoenplantsoen 26") -> B. Thoenplantsoen 26 | I7: =IFERROR(__xludf.DUMMYFUNCTION("""COMPUTED_VALUE"""),"2552JK") -> 2552JK | J7: =IFERROR(__xludf.DUMMYFUNCTION("""COMPUTED_VALUE"""),"s-Gravenhage") -> s-Gravenhage | K7: =IFERROR(__xludf.DUMMYFUNCTION("""COMPUTED_VALUE"""),"Nederland") -> Nederland | L7: =IFERROR(__xludf.DUMMYFUNCTION("""COMPUTED_VALUE"""),"Волянук") -> Волянук | M7: =IFERROR(__xludf.DUMMYFUNCTION("""COMPUTED_VALUE"""),45966.0) -> 45966 | N7: =IFERROR(__xludf.DUMMYFUNCTION("""COMPUTED_VALUE"""),"NL868638432B01") -> NL868638432B01 | O7: =IFERROR(__xludf.DUMMYFUNCTION("""COMPUTED_VALUE"""),9.8776592E7) -> 98776592 | P7: =IFERROR(__xludf.DUMMYFUNCTION("""COMPUTED_VALUE"""),"NL43INGB0117562858") -> NL43INGB0117562858 | Q7: =IFERROR(__xludf.DUMMYFUNCTION("""COMPUTED_VALUE"""),45966.0) -> 45966 | S7: =IFERROR(__xludf.DUMMYFUNCTION("""COMPUTED_VALUE"""),"NL868638432B01") -> NL868638432B01 | T7: =IFERROR(__xludf.DUMMYFUNCTION("""COMPUTED_VALUE"""),8.68638432E8) -> 868638432 | U7: =IFERROR(__xludf.DUMMYFUNCTION("""COMPUTED_VALUE"""),"Besloten Vennootschap") -> Besloten Vennootschap | V7: =IFERROR(__xludf.DUMMYFUNCTION("""COMPUTED_VALUE"""),"000063917092") -> 000063917092 | W7: =IFERROR(__xludf.DUMMYFUNCTION("""COMPUTED_VALUE"""),"ink.a1maatwerk.2288aa@zarabota.nl") -> ink.a1maatwerk.2288aa@zarabota.nl | X7: =IFERROR(__xludf.DUMMYFUNCTION("""COMPUTED_VALUE"""),"ver.a1maatwerk.2288aa@zarabota.nl") -> ver.a1maatwerk.2288aa@zarabota.nl | Y7: =IFERROR(__xludf.DUMMYFUNCTION("""COMPUTED_VALUE"""),"Hr.") -> Hr. | Z7: =IFERROR(__xludf.DUMMYFUNCTION("""COMPUTED_VALUE"""),"Anatoliy Viktorovich") -> Anatoliy Viktorovich | AA7: =IFERROR(__xludf.DUMMYFUNCTION("""COMPUTED_VALUE"""),"Volyanyuk") -> Volyanyuk | AB7: =IFERROR(__xludf.DUMMYFUNCTION("""COMPUTED_VALUE"""),"A.V.") -> A.V. | AC7: =IFERROR(__xludf.DUMMYFUNCTION("""COMPUTED_VALUE"""),5.65284769E8) -> 565284769 | AD7: =IFERROR(__xludf.DUMMYFUNCTION("""COMPUTED_VALUE"""),29473.0) -> 29473 | AE7: =IFERROR(__xludf.DUMMYFUNCTION("""COMPUTED_VALUE"""),"bg") -> bg | AF7: =IFERROR(__xludf.DUMMYFUNCTION("""COMPUTED_VALUE"""),"Zalozhtsi") -> Zalozhtsi | AG7: =IFERROR(__xludf.DUMMYFUNCTION("""COMPUTED_VALUE"""),"Hr. A.V. Volyanyuk") -> Hr. A.V. Volyanyuk | AN7: =IFERROR(__xludf.DUMMYFUNCTION("""COMPUTED_VALUE"""),"Anatoliy Viktorovich Volyanyuk") -> Anatoliy Viktorovich Volyanyuk | AO7: =IFERROR(__xludf.DUMMYFUNCTION("""COMPUTED_VALUE"""),1750.0) -> 1750
A8: =IFERROR(__xludf.DUMMYFUNCTION("""COMPUTED_VALUE"""),"ABZ Bouw") -> ABZ Bouw | B8: =IFERROR(__xludf.DUMMYFUNCTION("""COMPUTED_VALUE"""),"ABZ Bouw") -> ABZ Bouw | C8: =IFERROR(__xludf.DUMMYFUNCTION("""COMPUTED_VALUE"""),1680.0) -> 1680 | D8: =IFERROR(__xludf.DUMMYFUNCTION("""COMPUTED_VALUE"""),"Zdravko Dimitrov Kovachev") -> Zdravko Dimitrov Kovachev | E8: =IFERROR(__xludf.DUMMYFUNCTION("""COMPUTED_VALUE"""),"SBI-code: 4120 - Algemene burgerlijke en utiliteitsbouw") -> SBI-code: 4120 - Algemene burgerlijke en utiliteitsbouw | F8: =IFERROR(__xludf.DUMMYFUNCTION("""COMPUTED_VALUE"""),"0653958410") -> 0653958410 | G8: =IFERROR(__xludf.DUMMYFUNCTION("""COMPUTED_VALUE"""),"zdravkokovachev09@gmail.com") -> zdravkokovachev09@gmail.com | H8: =IFERROR(__xludf.DUMMYFUNCTION("""COMPUTED_VALUE"""),"Van Merlenstraat 58") -> Van Merlenstraat 58 | I8: =IFERROR(__xludf.DUMMYFUNCTION("""COMPUTED_VALUE"""),"2518TG") -> 2518TG | J8: =IFERROR(__xludf.DUMMYFUNCTION("""COMPUTED_VALUE"""),"s-Gravenhage") -> s-Gravenhage | K8: =IFERROR(__xludf.DUMMYFUNCTION("""COMPUTED_VALUE"""),"Nederland") -> Nederland | L8: =IFERROR(__xludf.DUMMYFUNCTION("""COMPUTED_VALUE"""),"Ковачев") -> Ковачев | M8: =IFERROR(__xludf.DUMMYFUNCTION("""COMPUTED_VALUE"""),45658.0) -> 45658 | N8: =IFERROR(__xludf.DUMMYFUNCTION("""COMPUTED_VALUE"""),"NL398790942B01") -> NL398790942B01 | O8: =IFERROR(__xludf.DUMMYFUNCTION("""COMPUTED_VALUE"""),8.9949382E7) -> 89949382 | P8: =IFERROR(__xludf.DUMMYFUNCTION("""COMPUTED_VALUE"""),"NL63INGB0104257687") -> NL63INGB0104257687 | Q8: =IFERROR(__xludf.DUMMYFUNCTION("""COMPUTED_VALUE"""),45034.0) -> 45034 | S8: =IFERROR(__xludf.DUMMYFUNCTION("""COMPUTED_VALUE"""),"NL004774766B22") -> NL004774766B22 | T8: =IFERROR(__xludf.DUMMYFUNCTION("""COMPUTED_VALUE"""),3.98790942E8) -> 398790942 | U8: =IFERROR(__xludf.DUMMYFUNCTION("""COMPUTED_VALUE"""),"Eenmanszaak") -> Eenmanszaak | V8: =IFERROR(__xludf.DUMMYFUNCTION("""COMPUTED_VALUE"""),"000055705510") -> 000055705510 | W8: =IFERROR(__xludf.DUMMYFUNCTION("""COMPUTED_VALUE"""),"ink.abzbouw.2288aa@zarabota.nl") -> ink.abzbouw.2288aa@zarabota.nl | X8: =IFERROR(__xludf.DUMMYFUNCTION("""COMPUTED_VALUE"""),"ver.abzbouw.2288aa@zarabota.nl") -> ver.abzbouw.2288aa@zarabota.nl | Y8: =IFERROR(__xludf.DUMMYFUNCTION("""COMPUTED_VALUE"""),"Hr.") -> Hr. | Z8: =IFERROR(__xludf.DUMMYFUNCTION("""COMPUTED_VALUE"""),"Zdravko Dimitrov") -> Zdravko Dimitrov | AA8: =IFERROR(__xludf.DUMMYFUNCTION("""COMPUTED_VALUE"""),"Kovachev") -> Kovachev | AB8: =IFERROR(__xludf.DUMMYFUNCTION("""COMPUTED_VALUE"""),"Z.D.") -> Z.D. | AC8: =IFERROR(__xludf.DUMMYFUNCTION("""COMPUTED_VALUE"""),3.98790942E8) -> 398790942 | AD8: =IFERROR(__xludf.DUMMYFUNCTION("""COMPUTED_VALUE"""),31064.0) -> 31064 | AE8: =IFERROR(__xludf.DUMMYFUNCTION("""COMPUTED_VALUE"""),"bg") -> bg | AF8: =IFERROR(__xludf.DUMMYFUNCTION("""COMPUTED_VALUE"""),"Madan") -> Madan | AG8: =IFERROR(__xludf.DUMMYFUNCTION("""COMPUTED_VALUE"""),"Hr. Z.D. Kovachev") -> Hr. Z.D. Kovachev | AJ8: =IFERROR(__xludf.DUMMYFUNCTION("""COMPUTED_VALUE"""),"ID Kaart") -> ID Kaart | AK8: =IFERROR(__xludf.DUMMYFUNCTION("""COMPUTED_VALUE"""),6.46769218E8) -> 646769218 | AL8: =IFERROR(__xludf.DUMMYFUNCTION("""COMPUTED_VALUE"""),46371.0) -> 46371 | AM8: =IFERROR(__xludf.DUMMYFUNCTION("""COMPUTED_VALUE"""),"Bulgarije") -> Bulgarije | AN8: =IFERROR(__xludf.DUMMYFUNCTION("""COMPUTED_VALUE"""),"Zdravko Dimitrov Kovachev") -> Zdravko Dimitrov Kovachev | AO8: =IFERROR(__xludf.DUMMYFUNCTION("""COMPUTED_VALUE"""),1680.0) -> 1680
A9: =IFERROR(__xludf.DUMMYFUNCTION("""COMPUTED_VALUE"""),"ADEN 71 LTD") -> ADEN 71 LTD | B9: =IFERROR(__xludf.DUMMYFUNCTION("""COMPUTED_VALUE"""),"ADEN 71 LTD") -> ADEN 71 LTD | C9: =IFERROR(__xludf.DUMMYFUNCTION("""COMPUTED_VALUE"""),0.0) -> 0 | D9: =IFERROR(__xludf.DUMMYFUNCTION("""COMPUTED_VALUE"""),"Svetozar Boyanov Semerdzhiev") -> Svetozar Boyanov Semerdzhiev | E9: =IFERROR(__xludf.DUMMYFUNCTION("""COMPUTED_VALUE"""),"SBI-code: 4941 - Goederenvervoer over de weg (geen verhuizingen)") -> SBI-code: 4941 - Goederenvervoer over de weg (geen verhuizingen) | F9: =IFERROR(__xludf.DUMMYFUNCTION("""COMPUTED_VALUE"""),"+359897829481") -> +359897829481 | G9: =IFERROR(__xludf.DUMMYFUNCTION("""COMPUTED_VALUE"""),"svetlio710623@gmail.com") -> svetlio710623@gmail.com | H9: =IFERROR(__xludf.DUMMYFUNCTION("""COMPUTED_VALUE"""),"Hristo Smirnenski 3") -> Hristo Smirnenski 3 | I9: =IFERROR(__xludf.DUMMYFUNCTION("""COMPUTED_VALUE"""),2000.0) -> 2000 | J9: =IFERROR(__xludf.DUMMYFUNCTION("""COMPUTED_VALUE"""),"Samokov") -> Samokov | K9: =IFERROR(__xludf.DUMMYFUNCTION("""COMPUTED_VALUE"""),"Bulgarije") -> Bulgarije | L9: =IFERROR(__xludf.DUMMYFUNCTION("""COMPUTED_VALUE"""),"Семерджиев") -> Семерджиев | M9: =IFERROR(__xludf.DUMMYFUNCTION("""COMPUTED_VALUE"""),46014.0) -> 46014 | N9: =IFERROR(__xludf.DUMMYFUNCTION("""COMPUTED_VALUE"""),"BG207227910") -> BG207227910 | O9: =IFERROR(__xludf.DUMMYFUNCTION("""COMPUTED_VALUE"""),2.0722791E8) -> 207227910 | P9: =IFERROR(__xludf.DUMMYFUNCTION("""COMPUTED_VALUE"""),"BG48 BPBI 7939 1480 5255 01") -> BG48 BPBI 7939 1480 5255 01 | Q9: =IFERROR(__xludf.DUMMYFUNCTION("""COMPUTED_VALUE"""),44945.0) -> 44945 | S9: =IFERROR(__xludf.DUMMYFUNCTION("""COMPUTED_VALUE"""),"BG207227910") -> BG207227910 | U9: =IFERROR(__xludf.DUMMYFUNCTION("""COMPUTED_VALUE"""),"Eenmanszaak") -> Eenmanszaak | Y9: =IFERROR(__xludf.DUMMYFUNCTION("""COMPUTED_VALUE"""),"Hr.") -> Hr. | Z9: =IFERROR(__xludf.DUMMYFUNCTION("""COMPUTED_VALUE"""),"Svetozar Boyanov") -> Svetozar Boyanov | AA9: =IFERROR(__xludf.DUMMYFUNCTION("""COMPUTED_VALUE"""),"Semerdzhiev") -> Semerdzhiev | AB9: =IFERROR(__xludf.DUMMYFUNCTION("""COMPUTED_VALUE"""),"S.B.") -> S.B. | AC9: =IFERROR(__xludf.DUMMYFUNCTION("""COMPUTED_VALUE"""),7.1062373E9) -> 7106237300 | AD9: =IFERROR(__xludf.DUMMYFUNCTION("""COMPUTED_VALUE"""),26107.0) -> 26107 | AE9: =IFERROR(__xludf.DUMMYFUNCTION("""COMPUTED_VALUE"""),"bg") -> bg | AF9: =IFERROR(__xludf.DUMMYFUNCTION("""COMPUTED_VALUE"""),"Sofia") -> Sofia | AG9: =IFERROR(__xludf.DUMMYFUNCTION("""COMPUTED_VALUE"""),"Hr. S.B. Semerdzhiev") -> Hr. S.B. Semerdzhiev | AJ9: =IFERROR(__xludf.DUMMYFUNCTION("""COMPUTED_VALUE"""),"ID Kaart") -> ID Kaart | AK9: =IFERROR(__xludf.DUMMYFUNCTION("""COMPUTED_VALUE"""),6.49310512E8) -> 649310512 | AL9: =IFERROR(__xludf.DUMMYFUNCTION("""COMPUTED_VALUE"""),47685.0) -> 47685 | AM9: =IFERROR(__xludf.DUMMYFUNCTION("""COMPUTED_VALUE"""),"Bulgarije") -> Bulgarije | AN9: =IFERROR(__xludf.DUMMYFUNCTION("""COMPUTED_VALUE"""),"Svetozar Boyanov Semerdzhiev") -> Svetozar Boyanov Semerdzhiev
A10: =IFERROR(__xludf.DUMMYFUNCTION("""COMPUTED_VALUE"""),"ADI 2018 VOF") -> ADI 2018 VOF | B10: =IFERROR(__xludf.DUMMYFUNCTION("""COMPUTED_VALUE"""),"ADI 2018 VOF") -> ADI 2018 VOF | C10: =IFERROR(__xludf.DUMMYFUNCTION("""COMPUTED_VALUE"""),513.0) -> 513 | D10: =IFERROR(__xludf.DUMMYFUNCTION("""COMPUTED_VALUE"""),"Avram Stoyanov Shopov") -> Avram Stoyanov Shopov | E10: =IFERROR(__xludf.DUMMYFUNCTION("""COMPUTED_VALUE"""),"SBI-code: 4120 - Algemene burgerlijke en utiliteitsbouw") -> SBI-code: 4120 - Algemene burgerlijke en utiliteitsbouw | F10: =IFERROR(__xludf.DUMMYFUNCTION("""COMPUTED_VALUE"""),"0645025254") -> 0645025254 | G10: =IFERROR(__xludf.DUMMYFUNCTION("""COMPUTED_VALUE"""),"anio198@abv.bg") -> anio198@abv.bg | H10: =IFERROR(__xludf.DUMMYFUNCTION("""COMPUTED_VALUE"""),"Jan van der Heydenstraat 4") -> Jan van der Heydenstraat 4 | I10: =IFERROR(__xludf.DUMMYFUNCTION("""COMPUTED_VALUE"""),"2522EP") -> 2522EP | J10: =IFERROR(__xludf.DUMMYFUNCTION("""COMPUTED_VALUE"""),"s-Gravenhage") -> s-Gravenhage | K10: =IFERROR(__xludf.DUMMYFUNCTION("""COMPUTED_VALUE"""),"Nederland") -> Nederland | L10: =IFERROR(__xludf.DUMMYFUNCTION("""COMPUTED_VALUE"""),"Шопов") -> Шопов | M10: =IFERROR(__xludf.DUMMYFUNCTION("""COMPUTED_VALUE"""),43132.0) -> 43132 | N10: =IFERROR(__xludf.DUMMYFUNCTION("""COMPUTED_VALUE"""),"NL858521544B01") -> NL858521544B01 | O10: =IFERROR(__xludf.DUMMYFUNCTION("""COMPUTED_VALUE"""),7.0947279E7) -> 70947279 | P10: =IFERROR(__xludf.DUMMYFUNCTION("""COMPUTED_VALUE"""),"NL24INGB0008227516") -> NL24INGB0008227516 | Q10: =IFERROR(__xludf.DUMMYFUNCTION("""COMPUTED_VALUE"""),43132.0) -> 43132 | S10: =IFERROR(__xludf.DUMMYFUNCTION("""COMPUTED_VALUE"""),"NL858521544B01") -> NL858521544B01 | T10: =IFERROR(__xludf.DUMMYFUNCTION("""COMPUTED_VALUE"""),8.58521544E8) -> 858521544 | U10: =IFERROR(__xludf.DUMMYFUNCTION("""COMPUTED_VALUE"""),"Eenmanszaak") -> Eenmanszaak | V10: =IFERROR(__xludf.DUMMYFUNCTION("""COMPUTED_VALUE"""),"000039172368") -> 000039172368 | W10: =IFERROR(__xludf.DUMMYFUNCTION("""COMPUTED_VALUE"""),"ink.adi2018vof.2288aa@zarabota.nl") -> ink.adi2018vof.2288aa@zarabota.nl | X10: =IFERROR(__xludf.DUMMYFUNCTION("""COMPUTED_VALUE"""),"ver.adi2018vof.2288aa@zarabota.nl") -> ver.adi2018vof.2288aa@zarabota.nl | Y10: =IFERROR(__xludf.DUMMYFUNCTION("""COMPUTED_VALUE"""),"Hr.") -> Hr. | Z10: =IFERROR(__xludf.DUMMYFUNCTION("""COMPUTED_VALUE"""),"Avram Stoyanov") -> Avram Stoyanov | AA10: =IFERROR(__xludf.DUMMYFUNCTION("""COMPUTED_VALUE"""),"Shopov") -> Shopov | AB10: =IFERROR(__xludf.DUMMYFUNCTION("""COMPUTED_VALUE"""),"A.S.") -> A.S. | AC10: =IFERROR(__xludf.DUMMYFUNCTION("""COMPUTED_VALUE"""),5.45568912E8) -> 545568912 | AD10: =IFERROR(__xludf.DUMMYFUNCTION("""COMPUTED_VALUE"""),29558.0) -> 29558 | AE10: =IFERROR(__xludf.DUMMYFUNCTION("""COMPUTED_VALUE"""),"bg") -> bg | AF10: =IFERROR(__xludf.DUMMYFUNCTION("""COMPUTED_VALUE"""),"Plovdiv") -> Plovdiv | AG10: =IFERROR(__xludf.DUMMYFUNCTION("""COMPUTED_VALUE"""),"Hr. A.S. Shopov") -> Hr. A.S. Shopov | AH10: =IFERROR(__xludf.DUMMYFUNCTION("""COMPUTED_VALUE"""),"NL59INGB0705080609") -> NL59INGB0705080609 | AJ10: =IFERROR(__xludf.DUMMYFUNCTION("""COMPUTED_VALUE"""),"ID Kaart") -> ID Kaart | AK10: =IFERROR(__xludf.DUMMYFUNCTION("""COMPUTED_VALUE"""),6.40994702E8) -> 640994702 | AL10: =IFERROR(__xludf.DUMMYFUNCTION("""COMPUTED_VALUE"""),44109.0) -> 44109 | AN10: =IFERROR(__xludf.DUMMYFUNCTION("""COMPUTED_VALUE"""),"Avram Stoyanov Shopov") -> Avram Stoyanov Shopov
A11: =IFERROR(__xludf.DUMMYFUNCTION("""COMPUTED_VALUE"""),"Adi1993") -> Adi1993 | B11: =IFERROR(__xludf.DUMMYFUNCTION("""COMPUTED_VALUE"""),"EXA Deliveries") -> EXA Deliveries | C11: =IFERROR(__xludf.DUMMYFUNCTION("""COMPUTED_VALUE"""),1748.0) -> 1748 | D11: =IFERROR(__xludf.DUMMYFUNCTION("""COMPUTED_VALUE"""),"Emil Adriyanov Yosifov") -> Emil Adriyanov Yosifov | E11: =IFERROR(__xludf.DUMMYFUNCTION("""COMPUTED_VALUE"""),"SBI-code: 4120 - Algemene burgerlijke en utiliteitsbouw") -> SBI-code: 4120 - Algemene burgerlijke en utiliteitsbouw | F11: =IFERROR(__xludf.DUMMYFUNCTION("""COMPUTED_VALUE"""),"0685819208") -> 0685819208 | G11: =IFERROR(__xludf.DUMMYFUNCTION("""COMPUTED_VALUE"""),"u4871973474@gmail.com") -> u4871973474@gmail.com | H11: =IFERROR(__xludf.DUMMYFUNCTION("""COMPUTED_VALUE"""),"Indigostraat 8A") -> Indigostraat 8A | I11: =IFERROR(__xludf.DUMMYFUNCTION("""COMPUTED_VALUE"""),"2563RJ") -> 2563RJ | J11: =IFERROR(__xludf.DUMMYFUNCTION("""COMPUTED_VALUE"""),"s-Gravenhage") -> s-Gravenhage | K11: =IFERROR(__xludf.DUMMYFUNCTION("""COMPUTED_VALUE"""),"Nederland") -> Nederland | L11: =IFERROR(__xludf.DUMMYFUNCTION("""COMPUTED_VALUE"""),"Йосифов") -> Йосифов | M11: =IFERROR(__xludf.DUMMYFUNCTION("""COMPUTED_VALUE"""),44927.0) -> 44927 | N11: =IFERROR(__xludf.DUMMYFUNCTION("""COMPUTED_VALUE"""),"NL301976387B02") -> NL301976387B02 | O11: =IFERROR(__xludf.DUMMYFUNCTION("""COMPUTED_VALUE"""),9.8796623E7) -> 98796623 | P11: =IFERROR(__xludf.DUMMYFUNCTION("""COMPUTED_VALUE"""),"NL71INGB0117513660") -> NL71INGB0117513660 | Q11: =IFERROR(__xludf.DUMMYFUNCTION("""COMPUTED_VALUE"""),45931.0) -> 45931 | S11: =IFERROR(__xludf.DUMMYFUNCTION("""COMPUTED_VALUE"""),"NL005354182B95") -> NL005354182B95 | T11: =IFERROR(__xludf.DUMMYFUNCTION("""COMPUTED_VALUE"""),3.01976387E8) -> 301976387 | U11: =IFERROR(__xludf.DUMMYFUNCTION("""COMPUTED_VALUE"""),"Eenmanszaak") -> Eenmanszaak | V11: =IFERROR(__xludf.DUMMYFUNCTION("""COMPUTED_VALUE"""),"000063935694") -> 000063935694 | W11: =IFERROR(__xludf.DUMMYFUNCTION("""COMPUTED_VALUE"""),"ink.exadeliveries.2288aa@zarabota.nl") -> ink.exadeliveries.2288aa@zarabota.nl | X11: =IFERROR(__xludf.DUMMYFUNCTION("""COMPUTED_VALUE"""),"ver.exadeliveries.2288aa@zarabota.nl") -> ver.exadeliveries.2288aa@zarabota.nl | Y11: =IFERROR(__xludf.DUMMYFUNCTION("""COMPUTED_VALUE"""),"Hr.") -> Hr. | Z11: =IFERROR(__xludf.DUMMYFUNCTION("""COMPUTED_VALUE"""),"Emil Adriyanov") -> Emil Adriyanov | AA11: =IFERROR(__xludf.DUMMYFUNCTION("""COMPUTED_VALUE"""),"Yosifov") -> Yosifov | AB11: =IFERROR(__xludf.DUMMYFUNCTION("""COMPUTED_VALUE"""),"E.A.") -> E.A. | AC11: =IFERROR(__xludf.DUMMYFUNCTION("""COMPUTED_VALUE"""),3.01976387E8) -> 301976387 | AD11: =IFERROR(__xludf.DUMMYFUNCTION("""COMPUTED_VALUE"""),33124.0) -> 33124 | AE11: =IFERROR(__xludf.DUMMYFUNCTION("""COMPUTED_VALUE"""),"bg") -> bg | AF11: =IFERROR(__xludf.DUMMYFUNCTION("""COMPUTED_VALUE"""),"Pleven") -> Pleven | AG11: =IFERROR(__xludf.DUMMYFUNCTION("""COMPUTED_VALUE"""),"Hr. E.A. Yosifov") -> Hr. E.A. Yosifov | AH11: =IFERROR(__xludf.DUMMYFUNCTION("""COMPUTED_VALUE"""),"NL96INGB0111824257") -> NL96INGB0111824257 | AJ11: =IFERROR(__xludf.DUMMYFUNCTION("""COMPUTED_VALUE"""),"ID Kaart") -> ID Kaart | AK11: =IFERROR(__xludf.DUMMYFUNCTION("""COMPUTED_VALUE"""),6.48487253E8) -> 648487253 | AL11: =IFERROR(__xludf.DUMMYFUNCTION("""COMPUTED_VALUE"""),47395.0) -> 47395 | AM11: =IFERROR(__xludf.DUMMYFUNCTION("""COMPUTED_VALUE"""),"Bulgarije") -> Bulgarije | AN11: =IFERROR(__xludf.DUMMYFUNCTION("""COMPUTED_VALUE"""),"Emil Adriyanov Yosifov") -> Emil Adriyanov Yosifov | AO11: =IFERROR(__xludf.DUMMYFUNCTION("""COMPUTED_VALUE"""),1748.0) -> 1748
A12: =IFERROR(__xludf.DUMMYFUNCTION("""COMPUTED_VALUE"""),"AdiMar Bouw") -> AdiMar Bouw | B12: =IFERROR(__xludf.DUMMYFUNCTION("""COMPUTED_VALUE"""),"AdiMar Bouw") -> AdiMar Bouw | C12: =IFERROR(__xludf.DUMMYFUNCTION("""COMPUTED_VALUE"""),1541.0) -> 1541 | D12: =IFERROR(__xludf.DUMMYFUNCTION("""COMPUTED_VALUE"""),"Adrian Marcinczyk") -> Adrian Marcinczyk | E12: =IFERROR(__xludf.DUMMYFUNCTION("""COMPUTED_VALUE"""),"SBI-code: 4120 - Algemene burgerlijke en utiliteitsbouw") -> SBI-code: 4120 - Algemene burgerlijke en utiliteitsbouw | F12: =IFERROR(__xludf.DUMMYFUNCTION("""COMPUTED_VALUE"""),"0687718709") -> 0687718709 | G12: =IFERROR(__xludf.DUMMYFUNCTION("""COMPUTED_VALUE"""),"adrianmarcinczyk5@gmail.com") -> adrianmarcinczyk5@gmail.com | H12: =IFERROR(__xludf.DUMMYFUNCTION("""COMPUTED_VALUE"""),"Obrecht 46") -> Obrecht 46 | I12: =IFERROR(__xludf.DUMMYFUNCTION("""COMPUTED_VALUE"""),"2681JM") -> 2681JM | J12: =IFERROR(__xludf.DUMMYFUNCTION("""COMPUTED_VALUE"""),"s-Gravenhage") -> s-Gravenhage | K12: =IFERROR(__xludf.DUMMYFUNCTION("""COMPUTED_VALUE"""),"Nederland") -> Nederland | L12: =IFERROR(__xludf.DUMMYFUNCTION("""COMPUTED_VALUE"""),"Marcinczyk") -> Marcinczyk | M12: =IFERROR(__xludf.DUMMYFUNCTION("""COMPUTED_VALUE"""),45180.0) -> 45180 | N12: =IFERROR(__xludf.DUMMYFUNCTION("""COMPUTED_VALUE"""),"NL664233387B01") -> NL664233387B01 | O12: =IFERROR(__xludf.DUMMYFUNCTION("""COMPUTED_VALUE"""),9.1673569E7) -> 91673569 | P12: =IFERROR(__xludf.DUMMYFUNCTION("""COMPUTED_VALUE"""),"NL43INGB0102660263") -> NL43INGB0102660263 | Q12: =IFERROR(__xludf.DUMMYFUNCTION("""COMPUTED_VALUE"""),45215.0) -> 45215 | S12: =IFERROR(__xludf.DUMMYFUNCTION("""COMPUTED_VALUE"""),"NL004907918B89") -> NL004907918B89 | T12: =IFERROR(__xludf.DUMMYFUNCTION("""COMPUTED_VALUE"""),6.64233387E8) -> 664233387 | U12: =IFERROR(__xludf.DUMMYFUNCTION("""COMPUTED_VALUE"""),"Eenmanszaak") -> Eenmanszaak | V12: =IFERROR(__xludf.DUMMYFUNCTION("""COMPUTED_VALUE"""),"000057337411") -> 000057337411 | W12: =IFERROR(__xludf.DUMMYFUNCTION("""COMPUTED_VALUE"""),"ink.adimar.2288aa@zarabota.nl") -> ink.adimar.2288aa@zarabota.nl | X12: =IFERROR(__xludf.DUMMYFUNCTION("""COMPUTED_VALUE"""),"ver.adimar.2288aa@zarabota.nl") -> ver.adimar.2288aa@zarabota.nl | Y12: =IFERROR(__xludf.DUMMYFUNCTION("""COMPUTED_VALUE"""),"Hr.") -> Hr. | Z12: =IFERROR(__xludf.DUMMYFUNCTION("""COMPUTED_VALUE"""),"Adrian") -> Adrian | AA12: =IFERROR(__xludf.DUMMYFUNCTION("""COMPUTED_VALUE"""),"Marcinczyk") -> Marcinczyk | AB12: =IFERROR(__xludf.DUMMYFUNCTION("""COMPUTED_VALUE"""),"A.") -> A. | AC12: =IFERROR(__xludf.DUMMYFUNCTION("""COMPUTED_VALUE"""),6.64233387E8) -> 664233387 | AD12: =IFERROR(__xludf.DUMMYFUNCTION("""COMPUTED_VALUE"""),37883.0) -> 37883 | AE12: =IFERROR(__xludf.DUMMYFUNCTION("""COMPUTED_VALUE"""),"pl") -> pl | AF12: =IFERROR(__xludf.DUMMYFUNCTION("""COMPUTED_VALUE"""),"Bialystok") -> Bialystok | AG12: =IFERROR(__xludf.DUMMYFUNCTION("""COMPUTED_VALUE"""),"Hr. A. Marcinczyk") -> Hr. A. Marcinczyk | AH12: =IFERROR(__xludf.DUMMYFUNCTION("""COMPUTED_VALUE"""),"NL64INGB0102659982") -> NL64INGB0102659982 | AJ12: =IFERROR(__xludf.DUMMYFUNCTION("""COMPUTED_VALUE"""),"ID Kaart") -> ID Kaart | AK12: =IFERROR(__xludf.DUMMYFUNCTION("""COMPUTED_VALUE"""),"CAL463693") -> CAL463693 | AL12: =IFERROR(__xludf.DUMMYFUNCTION("""COMPUTED_VALUE"""),45813.0) -> 45813 | AM12: =IFERROR(__xludf.DUMMYFUNCTION("""COMPUTED_VALUE"""),"Polen") -> Polen | AN12: =IFERROR(__xludf.DUMMYFUNCTION("""COMPUTED_VALUE"""),"Adrian Marcinczyk") -> Adrian Marcinczyk | AO12: =IFERROR(__xludf.DUMMYFUNCTION("""COMPUTED_VALUE"""),1541.0) -> 1541
A13: =IFERROR(__xludf.DUMMYFUNCTION("""COMPUTED_VALUE"""),"Adix Bouw") -> Adix Bouw | B13: =IFERROR(__xludf.DUMMYFUNCTION("""COMPUTED_VALUE"""),"Adix Bouw") -> Adix Bouw | C13: =IFERROR(__xludf.DUMMYFUNCTION("""COMPUTED_VALUE"""),1008.0) -> 1008 | D13: =IFERROR(__xludf.DUMMYFUNCTION("""COMPUTED_VALUE"""),"Petar Atanasov Mitev") -> Petar Atanasov Mitev | E13: =IFERROR(__xludf.DUMMYFUNCTION("""COMPUTED_VALUE"""),"SBI-code: 4120 - Algemene burgerlijke en utiliteitsbouw") -> SBI-code: 4120 - Algemene burgerlijke en utiliteitsbouw | F13: =IFERROR(__xludf.DUMMYFUNCTION("""COMPUTED_VALUE"""),"0684809083") -> 0684809083 | G13: =IFERROR(__xludf.DUMMYFUNCTION("""COMPUTED_VALUE"""),"peshoasd85@gmail.com") -> peshoasd85@gmail.com | H13: =IFERROR(__xludf.DUMMYFUNCTION("""COMPUTED_VALUE"""),"Hoefkade 491A") -> Hoefkade 491A | I13: =IFERROR(__xludf.DUMMYFUNCTION("""COMPUTED_VALUE"""),"2525LA") -> 2525LA | J13: =IFERROR(__xludf.DUMMYFUNCTION("""COMPUTED_VALUE"""),"s-Gravenhage") -> s-Gravenhage | K13: =IFERROR(__xludf.DUMMYFUNCTION("""COMPUTED_VALUE"""),"Nederland") -> Nederland | L13: =IFERROR(__xludf.DUMMYFUNCTION("""COMPUTED_VALUE"""),"Митев") -> Митев | M13: =IFERROR(__xludf.DUMMYFUNCTION("""COMPUTED_VALUE"""),44033.0) -> 44033 | N13: =IFERROR(__xludf.DUMMYFUNCTION("""COMPUTED_VALUE"""),"NL360984940B01") -> NL360984940B01 | O13: =IFERROR(__xludf.DUMMYFUNCTION("""COMPUTED_VALUE"""),7.8629713E7) -> 78629713 | P13: =IFERROR(__xludf.DUMMYFUNCTION("""COMPUTED_VALUE"""),"NL02INGB0007944381") -> NL02INGB0007944381 | Q13: =IFERROR(__xludf.DUMMYFUNCTION("""COMPUTED_VALUE"""),44033.0) -> 44033 | S13: =IFERROR(__xludf.DUMMYFUNCTION("""COMPUTED_VALUE"""),"NL003357920B16") -> NL003357920B16 | T13: =IFERROR(__xludf.DUMMYFUNCTION("""COMPUTED_VALUE"""),3.6098494E8) -> 360984940 | U13: =IFERROR(__xludf.DUMMYFUNCTION("""COMPUTED_VALUE"""),"Eenmanszaak") -> Eenmanszaak | V13: =IFERROR(__xludf.DUMMYFUNCTION("""COMPUTED_VALUE"""),"000046241558") -> 000046241558 | W13: =IFERROR(__xludf.DUMMYFUNCTION("""COMPUTED_VALUE"""),"ink.adixbouw.2288aa@zarabota.nl") -> ink.adixbouw.2288aa@zarabota.nl | X13: =IFERROR(__xludf.DUMMYFUNCTION("""COMPUTED_VALUE"""),"ver.adixbouw.2288aa@zarabota.nl") -> ver.adixbouw.2288aa@zarabota.nl | Y13: =IFERROR(__xludf.DUMMYFUNCTION("""COMPUTED_VALUE"""),"Hr.") -> Hr. | Z13: =IFERROR(__xludf.DUMMYFUNCTION("""COMPUTED_VALUE"""),"Petar Atanasov") -> Petar Atanasov | AA13: =IFERROR(__xludf.DUMMYFUNCTION("""COMPUTED_VALUE"""),"Mitev") -> Mitev | AB13: =IFERROR(__xludf.DUMMYFUNCTION("""COMPUTED_VALUE"""),"P.A.") -> P.A. | AC13: =IFERROR(__xludf.DUMMYFUNCTION("""COMPUTED_VALUE"""),3.6098494E8) -> 360984940 | AD13: =IFERROR(__xludf.DUMMYFUNCTION("""COMPUTED_VALUE"""),31271.0) -> 31271 | AE13: =IFERROR(__xludf.DUMMYFUNCTION("""COMPUTED_VALUE"""),"bg") -> bg | AF13: =IFERROR(__xludf.DUMMYFUNCTION("""COMPUTED_VALUE"""),"Haskovo") -> Haskovo | AG13: =IFERROR(__xludf.DUMMYFUNCTION("""COMPUTED_VALUE"""),"Hr. P.A. Mitev") -> Hr. P.A. Mitev | AH13: =IFERROR(__xludf.DUMMYFUNCTION("""COMPUTED_VALUE"""),"NL61INGB0799586218") -> NL61INGB0799586218 | AI13: =IFERROR(__xludf.DUMMYFUNCTION("""COMPUTED_VALUE"""),44028.0) -> 44028 | AJ13: =IFERROR(__xludf.DUMMYFUNCTION("""COMPUTED_VALUE"""),"ID Kaart") -> ID Kaart | AK13: =IFERROR(__xludf.DUMMYFUNCTION("""COMPUTED_VALUE"""),6.44982971E8) -> 644982971 | AL13: =IFERROR(__xludf.DUMMYFUNCTION("""COMPUTED_VALUE"""),45290.0) -> 45290 | AM13: =IFERROR(__xludf.DUMMYFUNCTION("""COMPUTED_VALUE"""),"Bulgarije") -> Bulgarije | AN13: =IFERROR(__xludf.DUMMYFUNCTION("""COMPUTED_VALUE"""),"Petar Atanasov Mitev") -> Petar Atanasov Mitev
A14: =IFERROR(__xludf.DUMMYFUNCTION("""COMPUTED_VALUE"""),"AFM Bouw") -> AFM Bouw | B14: =IFERROR(__xludf.DUMMYFUNCTION("""COMPUTED_VALUE"""),"AFM Bouw") -> AFM Bouw | C14: =IFERROR(__xludf.DUMMYFUNCTION("""COMPUTED_VALUE"""),9.0) -> 9 | D14: =IFERROR(__xludf.DUMMYFUNCTION("""COMPUTED_VALUE"""),"Milcho Yuriev Filipov") -> Milcho Yuriev Filipov | E14: =IFERROR(__xludf.DUMMYFUNCTION("""COMPUTED_VALUE"""),"SBI-code: 4120 - Algemene burgerlijke en utiliteitsbouw") -> SBI-code: 4120 - Algemene burgerlijke en utiliteitsbouw | F14: =IFERROR(__xludf.DUMMYFUNCTION("""COMPUTED_VALUE"""),"0620479796") -> 0620479796 | G14: =IFERROR(__xludf.DUMMYFUNCTION("""COMPUTED_VALUE"""),"amfbouw1@gmail.com") -> amfbouw1@gmail.com | H14: =IFERROR(__xludf.DUMMYFUNCTION("""COMPUTED_VALUE"""),"Van Diesenstraat 255") -> Van Diesenstraat 255 | I14: =IFERROR(__xludf.DUMMYFUNCTION("""COMPUTED_VALUE"""),"2521EH") -> 2521EH | J14: =IFERROR(__xludf.DUMMYFUNCTION("""COMPUTED_VALUE"""),"s-Gravenhage") -> s-Gravenhage | K14: =IFERROR(__xludf.DUMMYFUNCTION("""COMPUTED_VALUE"""),"Nederland") -> Nederland | L14: =IFERROR(__xludf.DUMMYFUNCTION("""COMPUTED_VALUE"""),"Филипов") -> Филипов | M14: =IFERROR(__xludf.DUMMYFUNCTION("""COMPUTED_VALUE"""),43175.0) -> 43175 | N14: =IFERROR(__xludf.DUMMYFUNCTION("""COMPUTED_VALUE"""),"NL425616083B01") -> NL425616083B01 | O14: =IFERROR(__xludf.DUMMYFUNCTION("""COMPUTED_VALUE"""),5.6661371E7) -> 56661371 | P14: =IFERROR(__xludf.DUMMYFUNCTION("""COMPUTED_VALUE"""),"NL03INGB0006326500") -> NL03INGB0006326500 | Q14: =IFERROR(__xludf.DUMMYFUNCTION("""COMPUTED_VALUE"""),41257.0) -> 41257 | S14: =IFERROR(__xludf.DUMMYFUNCTION("""COMPUTED_VALUE"""),"NL002482305B77") -> NL002482305B77 | T14: =IFERROR(__xludf.DUMMYFUNCTION("""COMPUTED_VALUE"""),4.25616083E8) -> 425616083 | U14: =IFERROR(__xludf.DUMMYFUNCTION("""COMPUTED_VALUE"""),"Eenmanszaak") -> Eenmanszaak | V14: =IFERROR(__xludf.DUMMYFUNCTION("""COMPUTED_VALUE"""),"000026189860") -> 000026189860 | W14: =IFERROR(__xludf.DUMMYFUNCTION("""COMPUTED_VALUE"""),"ink.afmbouw.2288aa@zarabota.nl") -> ink.afmbouw.2288aa@zarabota.nl | X14: =IFERROR(__xludf.DUMMYFUNCTION("""COMPUTED_VALUE"""),"ver.afmbouw.2288aa@zarabota.nl") -> ver.afmbouw.2288aa@zarabota.nl | Y14: =IFERROR(__xludf.DUMMYFUNCTION("""COMPUTED_VALUE"""),"Hr.") -> Hr. | Z14: =IFERROR(__xludf.DUMMYFUNCTION("""COMPUTED_VALUE"""),"Milcho Yuriev") -> Milcho Yuriev | AA14: =IFERROR(__xludf.DUMMYFUNCTION("""COMPUTED_VALUE"""),"Filipov") -> Filipov | AB14: =IFERROR(__xludf.DUMMYFUNCTION("""COMPUTED_VALUE"""),"M.Y.") -> M.Y. | AC14: =IFERROR(__xludf.DUMMYFUNCTION("""COMPUTED_VALUE"""),4.25616083E8) -> 425616083 | AD14: =IFERROR(__xludf.DUMMYFUNCTION("""COMPUTED_VALUE"""),26169.0) -> 26169 | AE14: =IFERROR(__xludf.DUMMYFUNCTION("""COMPUTED_VALUE"""),"bg") -> bg | AF14: =IFERROR(__xludf.DUMMYFUNCTION("""COMPUTED_VALUE"""),"Kardzhali") -> Kardzhali | AG14: =IFERROR(__xludf.DUMMYFUNCTION("""COMPUTED_VALUE"""),"Hr. M.Y. Filipov") -> Hr. M.Y. Filipov | AH14: =IFERROR(__xludf.DUMMYFUNCTION("""COMPUTED_VALUE"""),"NL91INGB0676668151") -> NL91INGB0676668151 | AI14: =IFERROR(__xludf.DUMMYFUNCTION("""COMPUTED_VALUE"""),41247.0) -> 41247 | AJ14: =IFERROR(__xludf.DUMMYFUNCTION("""COMPUTED_VALUE"""),"ID Kaart") -> ID Kaart | AK14: =IFERROR(__xludf.DUMMYFUNCTION("""COMPUTED_VALUE"""),6.44788891E8) -> 644788891 | AL14: =IFERROR(__xludf.DUMMYFUNCTION("""COMPUTED_VALUE"""),45202.0) -> 45202 | AN14: =IFERROR(__xludf.DUMMYFUNCTION("""COMPUTED_VALUE"""),"Milcho Yuriev Filipov") -> Milcho Yuriev Filipov
A15: =IFERROR(__xludf.DUMMYFUNCTION("""COMPUTED_VALUE"""),"Agora Boekhouding") -> Agora Boekhouding | B15: =IFERROR(__xludf.DUMMYFUNCTION("""COMPUTED_VALUE"""),"Agora Boekhouding - KOR per 01-04-2023") -> Agora Boekhouding - KOR per 01-04-2023 | C15: =IFERROR(__xludf.DUMMYFUNCTION("""COMPUTED_VALUE"""),902.0) -> 902 | D15: =IFERROR(__xludf.DUMMYFUNCTION("""COMPUTED_VALUE"""),"Hristina Atanasova Tyankova") -> Hristina Atanasova Tyankova | E15: =IFERROR(__xludf.DUMMYFUNCTION("""COMPUTED_VALUE"""),"SBI-code: 4120 - Algemene burgerlijke en utiliteitsbouw") -> SBI-code: 4120 - Algemene burgerlijke en utiliteitsbouw | F15: =IFERROR(__xludf.DUMMYFUNCTION("""COMPUTED_VALUE"""),"0611584401") -> 0611584401 | H15: =IFERROR(__xludf.DUMMYFUNCTION("""COMPUTED_VALUE"""),"Burgemeester Elsenlaan 329") -> Burgemeester Elsenlaan 329 | I15: =IFERROR(__xludf.DUMMYFUNCTION("""COMPUTED_VALUE"""),"2282MZ") -> 2282MZ | J15: =IFERROR(__xludf.DUMMYFUNCTION("""COMPUTED_VALUE"""),"s-Gravenhage") -> s-Gravenhage | K15: =IFERROR(__xludf.DUMMYFUNCTION("""COMPUTED_VALUE"""),"Nederland") -> Nederland | L15: =IFERROR(__xludf.DUMMYFUNCTION("""COMPUTED_VALUE"""),"Тянкова") -> Тянкова | M15: =IFERROR(__xludf.DUMMYFUNCTION("""COMPUTED_VALUE"""),42342.0) -> 42342 | N15: =IFERROR(__xludf.DUMMYFUNCTION("""COMPUTED_VALUE"""),"NL255501377B01") -> NL255501377B01 | O15: =IFERROR(__xludf.DUMMYFUNCTION("""COMPUTED_VALUE"""),5.9682132E7) -> 59682132 | P15: =IFERROR(__xludf.DUMMYFUNCTION("""COMPUTED_VALUE"""),"NL69ABNA0452140471") -> NL69ABNA0452140471 | Q15: =IFERROR(__xludf.DUMMYFUNCTION("""COMPUTED_VALUE"""),41649.0) -> 41649 | S15: =IFERROR(__xludf.DUMMYFUNCTION("""COMPUTED_VALUE"""),"NL002447245B76") -> NL002447245B76 | T15: =IFERROR(__xludf.DUMMYFUNCTION("""COMPUTED_VALUE"""),2.55501377E8) -> 255501377 | U15: =IFERROR(__xludf.DUMMYFUNCTION("""COMPUTED_VALUE"""),"Eenmanszaak") -> Eenmanszaak | V15: =IFERROR(__xludf.DUMMYFUNCTION("""COMPUTED_VALUE"""),"000028948882") -> 000028948882 | W15: =IFERROR(__xludf.DUMMYFUNCTION("""COMPUTED_VALUE"""),"ink.agoraboekhouding.2288aa@zarabota.nl") -> ink.agoraboekhouding.2288aa@zarabota.nl | X15: =IFERROR(__xludf.DUMMYFUNCTION("""COMPUTED_VALUE"""),"ver.agoraboekhouding.2288aa@zarabota.nl") -> ver.agoraboekhouding.2288aa@zarabota.nl | Y15: =IFERROR(__xludf.DUMMYFUNCTION("""COMPUTED_VALUE"""),"Mw.") -> Mw. | Z15: =IFERROR(__xludf.DUMMYFUNCTION("""COMPUTED_VALUE"""),"Hristina Atanasova") -> Hristina Atanasova | AA15: =IFERROR(__xludf.DUMMYFUNCTION("""COMPUTED_VALUE"""),"Tyankova") -> Tyankova | AB15: =IFERROR(__xludf.DUMMYFUNCTION("""COMPUTED_VALUE"""),"H.A.") -> H.A. | AC15: =IFERROR(__xludf.DUMMYFUNCTION("""COMPUTED_VALUE"""),2.55501377E8) -> 255501377 | AD15: =IFERROR(__xludf.DUMMYFUNCTION("""COMPUTED_VALUE"""),25518.0) -> 25518 | AE15: =IFERROR(__xludf.DUMMYFUNCTION("""COMPUTED_VALUE"""),"bg") -> bg | AF15: =IFERROR(__xludf.DUMMYFUNCTION("""COMPUTED_VALUE"""),"Asenovgrad") -> Asenovgrad | AG15: =IFERROR(__xludf.DUMMYFUNCTION("""COMPUTED_VALUE"""),"Mw. H.A. Tyankova") -> Mw. H.A. Tyankova | AM15: =IFERROR(__xludf.DUMMYFUNCTION("""COMPUTED_VALUE"""),"Bulgarije") -> Bulgarije | AN15: =IFERROR(__xludf.DUMMYFUNCTION("""COMPUTED_VALUE"""),"Hristina Atanasova Tyankova") -> Hristina Atanasova Tyankova
A16: =IFERROR(__xludf.DUMMYFUNCTION("""COMPUTED_VALUE"""),"AHF31") -> AHF31 | B16: =IFERROR(__xludf.DUMMYFUNCTION("""COMPUTED_VALUE"""),"AHF31 - KOR") -> AHF31 - KOR | C16: =IFERROR(__xludf.DUMMYFUNCTION("""COMPUTED_VALUE"""),685.0) -> 685 | D16: =IFERROR(__xludf.DUMMYFUNCTION("""COMPUTED_VALUE"""),"Anka Hubenova Filipova") -> Anka Hubenova Filipova | E16: =IFERROR(__xludf.DUMMYFUNCTION("""COMPUTED_VALUE"""),"SBI-code: 4120 - Algemene burgerlijke en utiliteitsbouw") -> SBI-code: 4120 - Algemene burgerlijke en utiliteitsbouw | F16: =IFERROR(__xludf.DUMMYFUNCTION("""COMPUTED_VALUE"""),"0657454758") -> 0657454758 | G16: =IFERROR(__xludf.DUMMYFUNCTION("""COMPUTED_VALUE"""),"ahfilipova31@gmail.com") -> ahfilipova31@gmail.com | H16: =IFERROR(__xludf.DUMMYFUNCTION("""COMPUTED_VALUE"""),"Van Diesenstraat 255") -> Van Diesenstraat 255 | I16: =IFERROR(__xludf.DUMMYFUNCTION("""COMPUTED_VALUE"""),"2521EH") -> 2521EH | J16: =IFERROR(__xludf.DUMMYFUNCTION("""COMPUTED_VALUE"""),"s-Gravenhage") -> s-Gravenhage | K16: =IFERROR(__xludf.DUMMYFUNCTION("""COMPUTED_VALUE"""),"Nederland") -> Nederland | L16: =IFERROR(__xludf.DUMMYFUNCTION("""COMPUTED_VALUE"""),"Филипова") -> Филипова | M16: =IFERROR(__xludf.DUMMYFUNCTION("""COMPUTED_VALUE"""),43466.0) -> 43466 | N16: =IFERROR(__xludf.DUMMYFUNCTION("""COMPUTED_VALUE"""),"NL611922071B01") -> NL611922071B01 | O16: =IFERROR(__xludf.DUMMYFUNCTION("""COMPUTED_VALUE"""),7.3721948E7) -> 73721948 | P16: =IFERROR(__xludf.DUMMYFUNCTION("""COMPUTED_VALUE"""),"NL50INGB0008768987") -> NL50INGB0008768987 | Q16: =IFERROR(__xludf.DUMMYFUNCTION("""COMPUTED_VALUE"""),43466.0) -> 43466 | S16: =IFERROR(__xludf.DUMMYFUNCTION("""COMPUTED_VALUE"""),"NL002507747B19") -> NL002507747B19 | T16: =IFERROR(__xludf.DUMMYFUNCTION("""COMPUTED_VALUE"""),6.11922071E8) -> 611922071 | U16: =IFERROR(__xludf.DUMMYFUNCTION("""COMPUTED_VALUE"""),"Eenmanszaak") -> Eenmanszaak | V16: =IFERROR(__xludf.DUMMYFUNCTION("""COMPUTED_VALUE"""),"000041730836") -> 000041730836 | W16: =IFERROR(__xludf.DUMMYFUNCTION("""COMPUTED_VALUE"""),"ink.ahf31.2288aa@zarabota.nl") -> ink.ahf31.2288aa@zarabota.nl | X16: =IFERROR(__xludf.DUMMYFUNCTION("""COMPUTED_VALUE"""),"ver.ahf31.2288aa@zarabota.nl") -> ver.ahf31.2288aa@zarabota.nl | Y16: =IFERROR(__xludf.DUMMYFUNCTION("""COMPUTED_VALUE"""),"Mw.") -> Mw. | Z16: =IFERROR(__xludf.DUMMYFUNCTION("""COMPUTED_VALUE"""),"Anka Hubenova") -> Anka Hubenova | AA16: =IFERROR(__xludf.DUMMYFUNCTION("""COMPUTED_VALUE"""),"Filipova") -> Filipova | AB16: =IFERROR(__xludf.DUMMYFUNCTION("""COMPUTED_VALUE"""),"A.H.") -> A.H. | AC16: =IFERROR(__xludf.DUMMYFUNCTION("""COMPUTED_VALUE"""),6.11922071E8) -> 611922071 | AD16: =IFERROR(__xludf.DUMMYFUNCTION("""COMPUTED_VALUE"""),26298.0) -> 26298 | AE16: =IFERROR(__xludf.DUMMYFUNCTION("""COMPUTED_VALUE"""),"bg") -> bg | AF16: =IFERROR(__xludf.DUMMYFUNCTION("""COMPUTED_VALUE"""),"Avren") -> Avren | AG16: =IFERROR(__xludf.DUMMYFUNCTION("""COMPUTED_VALUE"""),"Mw. A.H. Filipova") -> Mw. A.H. Filipova | AN16: =IFERROR(__xludf.DUMMYFUNCTION("""COMPUTED_VALUE"""),"Anka Hubenova Filipova") -> Anka Hubenova Filipova
A17: =IFERROR(__xludf.DUMMYFUNCTION("""COMPUTED_VALUE"""),"Ahmed 82") -> Ahmed 82 | B17: =IFERROR(__xludf.DUMMYFUNCTION("""COMPUTED_VALUE"""),"Ahmed 82") -> Ahmed 82 | C17: =IFERROR(__xludf.DUMMYFUNCTION("""COMPUTED_VALUE"""),426.0) -> 426 | D17: =IFERROR(__xludf.DUMMYFUNCTION("""COMPUTED_VALUE"""),"Ahmed Hilmi Kenan") -> Ahmed Hilmi Kenan | E17: =IFERROR(__xludf.DUMMYFUNCTION("""COMPUTED_VALUE"""),"SBI-code: 4120 - Algemene burgerlijke en utiliteitsbouw") -> SBI-code: 4120 - Algemene burgerlijke en utiliteitsbouw | F17: =IFERROR(__xludf.DUMMYFUNCTION("""COMPUTED_VALUE"""),"0645089701") -> 0645089701 | G17: =IFERROR(__xludf.DUMMYFUNCTION("""COMPUTED_VALUE"""),"ahmedkenan82@gmail.com") -> ahmedkenan82@gmail.com | H17: =IFERROR(__xludf.DUMMYFUNCTION("""COMPUTED_VALUE"""),"Barneveldstraat 17") -> Barneveldstraat 17 | I17: =IFERROR(__xludf.DUMMYFUNCTION("""COMPUTED_VALUE"""),"2573WB") -> 2573WB | J17: =IFERROR(__xludf.DUMMYFUNCTION("""COMPUTED_VALUE"""),"s-Gravenhage") -> s-Gravenhage | K17: =IFERROR(__xludf.DUMMYFUNCTION("""COMPUTED_VALUE"""),"Nederland") -> Nederland | L17: =IFERROR(__xludf.DUMMYFUNCTION("""COMPUTED_VALUE"""),"Кенан") -> Кенан | M17: =IFERROR(__xludf.DUMMYFUNCTION("""COMPUTED_VALUE"""),43175.0) -> 43175 | N17: =IFERROR(__xludf.DUMMYFUNCTION("""COMPUTED_VALUE"""),"NL655200046B01") -> NL655200046B01 | O17: =IFERROR(__xludf.DUMMYFUNCTION("""COMPUTED_VALUE"""),6.9009449E7) -> 69009449 | P17: =IFERROR(__xludf.DUMMYFUNCTION("""COMPUTED_VALUE"""),"NL46INGB0007822339") -> NL46INGB0007822339 | Q17: =IFERROR(__xludf.DUMMYFUNCTION("""COMPUTED_VALUE"""),42901.0) -> 42901 | S17: =IFERROR(__xludf.DUMMYFUNCTION("""COMPUTED_VALUE"""),"NL002513371B37") -> NL002513371B37 | T17: =IFERROR(__xludf.DUMMYFUNCTION("""COMPUTED_VALUE"""),6.55200046E8) -> 655200046 | U17: =IFERROR(__xludf.DUMMYFUNCTION("""COMPUTED_VALUE"""),"Eenmanszaak") -> Eenmanszaak | V17: =IFERROR(__xludf.DUMMYFUNCTION("""COMPUTED_VALUE"""),"000037400126") -> 000037400126 | W17: =IFERROR(__xludf.DUMMYFUNCTION("""COMPUTED_VALUE"""),"ink.ahmed82.2288aa@zarabota.nl") -> ink.ahmed82.2288aa@zarabota.nl | X17: =IFERROR(__xludf.DUMMYFUNCTION("""COMPUTED_VALUE"""),"ver.ahmed82.2288aa@zarabota.nl") -> ver.ahmed82.2288aa@zarabota.nl | Y17: =IFERROR(__xludf.DUMMYFUNCTION("""COMPUTED_VALUE"""),"Hr.") -> Hr. | Z17: =IFERROR(__xludf.DUMMYFUNCTION("""COMPUTED_VALUE"""),"Ahmed Hilmi") -> Ahmed Hilmi | AA17: =IFERROR(__xludf.DUMMYFUNCTION("""COMPUTED_VALUE"""),"Kenan") -> Kenan | AB17: =IFERROR(__xludf.DUMMYFUNCTION("""COMPUTED_VALUE"""),"A.H.") -> A.H. | AC17: =IFERROR(__xludf.DUMMYFUNCTION("""COMPUTED_VALUE"""),6.55200046E8) -> 655200046 | AD17: =IFERROR(__xludf.DUMMYFUNCTION("""COMPUTED_VALUE"""),30130.0) -> 30130 | AE17: =IFERROR(__xludf.DUMMYFUNCTION("""COMPUTED_VALUE"""),"bg") -> bg | AF17: =IFERROR(__xludf.DUMMYFUNCTION("""COMPUTED_VALUE"""),"Ardino") -> Ardino | AG17: =IFERROR(__xludf.DUMMYFUNCTION("""COMPUTED_VALUE"""),"Hr. A.H. Kenan") -> Hr. A.H. Kenan | AN17: =IFERROR(__xludf.DUMMYFUNCTION("""COMPUTED_VALUE"""),"Ahmed Hilmi Kenan") -> Ahmed Hilmi Kenan
